Workbook

Sheet Summary
A1: Website Clicks Improver - Harbour Dental (fictional example)
A2: GSC data: Last 3 months (sample data) | Mode: page+query | Generated 2026-10-21
A4: Clicks in the data | B4: 4613
A5: Impressions in the data | B5: 123661
A6: Site CTR | B6: =IFERROR(B4/B5,0)
A7: Low-CTR pages on page 1 | B7: =COUNTA('Low CTR Pages'!A:A)-1
A8: Extra clicks if they hit expected CTR | B8: =SUM('Low CTR Pages'!H:H)
A9: Pages stuck on Google page 2-3 | B9: =COUNTA('Page 2-3 Pages'!A:A)-1
A10: Clicks if those pages reach position 5 | B10: =SUM('Page 2-3 Pages'!G:G)
A11: Total click opportunity (per period) | B11: =B8+B10
A12: Keyword gaps (ranking but not used) | B12: =COUNTA('Keyword Gaps'!B:B)-1
A13: Content chunks written | B13: =COUNTIF('Content Chunks'!J:J,">0")
A14: Actions done | B14: =COUNTIF('Action Plan'!H:H,"Done")&" of "&(COUNTA('Action Plan'!A:A)-1)
A16: Top 10 actions
A17: Action | B17: Priority | C17: Page | D17: Type | E17: Est. extra clicks
A18: Add 4 content chunks + 1 internal link; follow the push plan (see Page 2-3 Pages) | B18: High | C18: /services/dental-implants/ | D18: Push to page 1 | E18: 803
A19: Add 4 content chunks; follow the push plan (see Page 2-3 Pages) | B19: High | C19: /services/root-canal/ | D19: Push to page 1 | E19: 546
A20: Rewrite title + meta description (see Low CTR Pages) | B20: High | C20: /services/teeth-whitening/ | D20: CTR rewrite | E20: 498
A21: Add 1 content chunk + 1 internal link; follow the push plan (see Page 2-3 Pages) | B21: Medium | C21: /blog/teeth-whitening-cost/ | D21: Push to page 1 | E21: 397
A22: Rewrite title + meta description (see Low CTR Pages) | B22: Medium | C22: /services/invisalign/ | D22: CTR rewrite | E22: 124
A23: Rewrite title + meta description (see Low CTR Pages) | B23: Medium | C23: /blog/invisalign-vs-braces/ | D23: CTR rewrite | E23: 98
A24: Add 6 content chunks for keywords the page ranks for but doesn't use | B24: Medium | C24: /services/teeth-whitening/ | D24: Content chunks
A25: Add 4 content chunks for keywords the page ranks for but doesn't use | B25: Medium | C25: /services/invisalign/ | D25: Content chunks
A26: Add 1 content chunk for keywords the page ranks for but doesn't use | B26: Medium | C26: /blog/invisalign-vs-braces/ | D26: Content chunks
A27: Add 4 content chunks for keywords the page ranks for but doesn't use | B27: Medium | C27: /blog/how-long-do-dental-implants-last/ | D27: Content chunks
A29: How to use this workbook
A30: 1. Low CTR Pages: paste the suggested title + meta into your CMS (check the char counts stay green).
A31: 2. Page 2-3 Pages: work through the push plan, starting with High priority rows.
A32: 3. Content Chunks: add each chunk where it says, in your own voice. Check every fact flagged in 'Check before publishing'.
A33: 4. Internal Links: add a contextual link from each source page using the suggested anchor.
A34: 5. Action Plan: set an owner and mark Status as you go. Re-check GSC 4-6 weeks after each change.
A37: Built with website-clicks-improver by Akif Qureshi | SEO Specialist - algoblueprints.com

Sheet Low CTR Pages
A1: Page URL | B1: Clicks | C1: Impressions | D1: CTR | E1: Avg position | F1: Expected CTR | G1: CTR vs expected | H1: Extra clicks at expected CTR | I1: Priority | J1: Top queries | K1: Current title | L1: Title chars | M1: Current meta description | N1: Meta chars | O1: Snippet issues found | P1: Diagnosis | Q1: Suggested title (recommended) | R1: New title chars | S1: Alternative title | T1: Alt title chars | U1: Suggested meta description | V1: New meta chars | W1: Alternative meta description | X1: Alt meta chars | Y1: Other fixes | Z1: Status
A2: https://www.harbourdental.example/services/teeth-whitening/ | B2: 512 | C2: 24329 | D2: =IFERROR(B2/C2,0) | E2: 5.9 | F2: 0.0415 | G2: =IFERROR(D2/F2,0) | H2: =MAX(0,ROUND(C2*F2-B2,0)) | I2: High | J2: teeth whitening (6,589 impr, pos 6.8) teeth whitening parramatta (4,360 impr, pos 3.3) teeth whitening near me (2,256 impr, pos 3.2) teeth whitening cost (2,070 impr, pos 12.7) professional teeth whitening (1,439 impr, pos 3.5) how long does teeth whitening last (994 impr, pos 7.0) | K2: Teeth Whitening Services | Harbour Dental Clinic Parramatta NSW Australia | L2: =LEN(K2) | M2: Harbour Dental offers teeth whitening. | N2: =LEN(M2) | O2: - Title is 73 chars - likely truncated in Google (aim for 50-60). - Meta description is only 38 chars - too thin to sell the click. | P2: Ranks about #3 for 'teeth whitening parramatta' and 'teeth whitening near me' (6,600+ impressions) but earns less than half the CTR that position should get. The 73-char title is cut off before it says anything useful, and the 38-char meta gives searchers no reason to pick this result. | Q2: Teeth Whitening Parramatta | Brighter Smile in One Visit | R2: =LEN(Q2) | S2: Professional Teeth Whitening in Parramatta | Harbour Dental | T2: =LEN(S2) | U2: Professional teeth whitening in Parramatta: in-chair results in about an hour, plus custom take-home kits to keep your smile bright. Book online today. | V2: =LEN(U2) | W2: Whiter teeth in one visit at Harbour Dental Parramatta. Dentist-checked in-chair whitening and custom take-home kits. Open six days. Book online now. | X2: =LEN(W2) | Y2: - H1: Professional Teeth Whitening in Parramatta - Add the FAQ block (chunk C4): question searches bring ~1,600 impressions a period - Let /blog/teeth-whitening-cost/ own 'teeth whitening cost' (both pages compete for it). Add a short price teaser + link (chunk C2) instead of a full price section here | Z2: To do
A3: https://www.harbourdental.example/services/invisalign/ | B3: 128 | C3: 10872 | D3: =IFERROR(B3/C3,0) | E3: 8.7 | F3: 0.0232 | G3: =IFERROR(D3/F3,0) | H3: =MAX(0,ROUND(C3*F3-B3,0)) | I3: Medium | J3: invisalign cost (3,226 impr, pos 9.6) invisalign parramatta (1,938 impr, pos 5.1) clear aligners (1,378 impr, pos 11.6) invisalign provider near me (915 impr, pos 6.5) how long does invisalign take (715 impr, pos 10.6) invisalign payment plans (560 impr, pos 10.2) | K3: Invisalign | L3: =LEN(K3) | N3: =LEN(M3) | O3: - Title is only 10 chars - wasted space in the result; add the main keyword and a reason to click. - No meta description - Google writes its own snippet, often a weak one. - Top query 'invisalign cost' is not in the title. - 43% of impressions are price searches but title/meta never mention price or cost. | P3: 43% of impressions are price searches ('invisalign cost', 'invisalign payment plans'), but the title is just 'Invisalign' (10 chars) and there is no meta description. The result gives price-shoppers no reason to pick it over clinics that show prices. | Q3: Invisalign Parramatta: Cost & Payment Plans Explained | R3: =LEN(Q3) | S3: Invisalign Cost in Parramatta | Clear Aligners from [price] | T3: =LEN(S3) | U3: Invisalign in Parramatta from [price], with payment plans to spread the cost. A 3D scan shows how your teeth will move before you start. Book a consult. | V3: =LEN(U3) | W3: Thinking about Invisalign in Parramatta? See what clear aligners cost, how long treatment takes and how payment plans work. Book your 3D scan today. | X3: =LEN(W3) | Y3: - H1: Invisalign Clear Aligners in Parramatta - Confirm the starting price and payment-plan details before publishing (placeholders in title/meta) - Add the pricing section (chunk C1) so the page delivers what the new snippet promises | Z3: To do
A4: https://www.harbourdental.example/blog/invisalign-vs-braces/ | B4: 57 | C4: 7063 | D4: =IFERROR(B4/C4,0) | E4: 9 | F4: 0.022 | G4: =IFERROR(D4/F4,0) | H4: =MAX(0,ROUND(C4*F4-B4,0)) | I4: Medium | J4: invisalign vs braces (3,262 impr, pos 7.5) invisalign vs braces cost (1,109 impr, pos 10.7) braces or invisalign for adults (694 impr, pos 10.3) invisalign vs braces pros and cons (579 impr, pos 10.6) which is faster invisalign or braces (393 impr, pos 11.5) | K4: Blog | Harbour Dental | L4: =LEN(K4) | M4: Read our latest article from the Harbour Dental team. | N4: =LEN(M4) | O4: - Title is only 21 chars - wasted space in the result; add the main keyword and a reason to click. - Meta description is only 53 chars - too thin to sell the click. - Top query 'invisalign vs braces' is not in the title. - Meta description does not mention the top query 'invisalign vs braces'. - Title does not match what people search for this page (generic title). - 100% of impressions are comparison searches - a comparison table would match intent. | P4: Every impression is a comparison search, but the title tag is the blog template 'Blog | Harbour Dental' and the meta is boilerplate. Searchers can't tell this is the Invisalign vs braces comparison they want, so they click the results that say it. | Q4: Invisalign vs Braces: Cost, Speed & Comfort Compared | R4: =LEN(Q4) | S4: Invisalign or Braces for Adults? Pros, Cons & Costs | T4: =LEN(S4) | U4: Invisalign vs braces compared side by side: cost, treatment time, comfort and looks. Find out which suits adults and teens best, from a Parramatta dentist. | V4: =LEN(U4) | W4: Braces or Invisalign? Compare cost, how fast each works, pros and cons, and which is better for adults. Clear table plus a dentist's honest verdict. | X4: =LEN(W4) | Y4: - Fix the blog template so every post uses its own title tag, not 'Blog | Harbour Dental' (check other posts too) - Add the comparison table (chunk C1) right after the intro so the page matches the comparison intent | Z4: To do
A5: https://www.harbourdental.example/blog/how-long-do-dental-implants-last/ | B5: 74 | C5: 5763 | D5: =IFERROR(B5/C5,0) | E5: 8.8 | F5: 0.0228 | G5: =IFERROR(D5/F5,0) | H5: =MAX(0,ROUND(C5*F5-B5,0)) | I5: Low | J5: how long do dental implants last (2,673 impr, pos 7.0) dental implant lifespan (991 impr, pos 8.9) do dental implants last forever (682 impr, pos 8.4) dental implant failure signs (501 impr, pos 14.9) implant vs bridge longevity (280 impr, pos 14.9) | K5: How Long Do Dental Implants Last? | Harbour Dental | L5: =LEN(K5) | M5: How long do dental implants last? Learn about dental implants and how long they last. | N5: =LEN(M5) | O5: - No obvious title/meta fault - check the live SERP: an AI Overview, featured snippet, People Also Ask, local pack or ads may be taking the clicks. Also confirm Google shows your title/meta and not a rewrite. | P5: Title and meta are on-topic, so the snippet isn't the main problem. For a question like 'how long do dental implants last', Google likely answers in an AI Overview or featured snippet, so fewer people need to click. Check the live SERP. Then win the answer box with a 40-60 word answer under the H1, and give the snippet a reason to click (implant vs crown lifespan, warning signs). | Q5: How Long Do Dental Implants Last? Lifespan & Warning Signs | R5: =LEN(Q5) | S5: Do Dental Implants Last Forever? Implant vs Crown Lifespan | T5: =LEN(S5) | U5: With good care an implant post can last for decades, while the crown on top usually lasts 10-15 years. See what shortens implant life and warning signs. | V5: =LEN(U5) | W5: Dental implants can last a lifetime, but the crown wears out sooner. See typical lifespans, what affects them, signs of failure and how to protect yours. | X5: =LEN(W5) | Y5: - Add a 40-60 word direct answer as the first paragraph: post lasts decades with care, crown typically 10-15 years - Add Article schema with datePublished/dateModified and show the updated date on the page | Z5: To do

Sheet Page 2-3 Pages
A1: Page URL | B1: SERP page | C1: Clicks | D1: Impressions | E1: Avg position | F1: CTR | G1: Est. clicks at position 5 | H1: Priority | I1: Keywords on page 2-3 | J1: Word count | K1: Keyword gaps | L1: Diagnosis | M1: Push-to-page-1 plan | N1: Internal links to add | O1: Suggested title / H1 (optional) | P1: Title chars | Q1: Status
A2: https://www.harbourdental.example/services/dental-implants/ | B2: =IF(E2<21,2,3) | C2: 131 | D2: 16978 | E2: 17.8 | F2: =IFERROR(C2/D2,0) | G2: =MAX(0,ROUND(D2*'Method & Notes'!$B$12-C2,0)) | H2: High | I2: dental implants (pos 20.2, 5,497 impr) dental implants cost (pos 18.1, 4,035 impr) dental implants parramatta (pos 11.1, 1,764 impr) all on 4 dental implants (pos 19.5, 1,517 impr) single tooth implant (pos 15.2, 947 impr) are dental implants painful (pos 14.6, 540 impr) dental implants payment plan (pos 16.1, 367 impr) | J2: 104 | K2: =COUNTIF('Keyword Gaps'!$A:$A,A2) | L2: Ranks 11-20 for seven implant queries but never mentions cost, even though 'dental implants cost' alone brings 4,000+ impressions. Searches for All-on-4 and single-tooth implants also land here with nothing to answer them. At about 90 words the page is far thinner than the guides that typically rank top 3. | M2: 1. Add chunk C1 (pricing section: 'dental implants cost', 'payment plan', 4,402 impressions) right after the intro 2. Add chunks C2 (All-on-4) and C3 (single tooth implant) as new H2 sections: 2,464 impressions currently land on a page that never mentions them 3. Add the FAQ (chunk C4, 'Are dental implants painful?') before 'Why choose Harbour Dental' 4. Internal links: from /blog/how-long-do-dental-implants-last/ (anchor 'dental implants') and from the homepage services block 5. Update the title to 'Dental Implants Parramatta | Cost, All-on-4 & Single Tooth' once the new sections are live 6. Add trust signals: implant dentist bio, years of experience, real before/after photos, implant brand and warranty | N2: /blog/how-long-do-dental-implants-last/ -> anchor 'dental implants' | P2: =IF(LEN(O2)=0,0,IFERROR(FIND(CHAR(10),O2)-1,LEN(O2))) | Q2: To do
A3: https://www.harbourdental.example/services/root-canal/ | B3: =IF(E3<21,2,3) | C3: 50 | D3: 10832 | E3: 24.7 | F3: =IFERROR(C3/D3,0) | G3: =MAX(0,ROUND(D3*'Method & Notes'!$B$12-C3,0)) | H3: High | I3: root canal treatment (pos 26.2, 3,352 impr) root canal cost (pos 24.6, 2,228 impr) does a root canal hurt (pos 23.7, 1,138 impr) root canal parramatta (pos 20.0, 1,029 impr) root canal recovery time (pos 25.8, 801 impr) | J3: 86 | K3: =COUNTIF('Keyword Gaps'!$A:$A,A3) | L3: Page 3 (pos ~25) for 'root canal treatment' (3,350 impressions) with a page of about 90 words. The queries show people want cost, pain and recovery answers, and the page covers none of them. This needs an expansion, not tweaks. | M3: 1. Expand the page to a full root canal guide (aim to cover: signs, steps, pain, recovery, cost, aftercare) using chunks C1-C4 2. Add chunk C1 (cost section) and chunk C4 (recovery time) as new H2s; add the FAQ chunk C2 ('Does a root canal hurt?') 3. Work 'root canal treatment in Parramatta' into the intro and H1 (chunk C3) 4. Link from /services/emergency-dentist/ (782 clicks; toothache visitors often need a root canal) with anchor 'root canal treatment' 5. Link from /services/dental-crowns/ where it mentions crowns after root canals 6. Request indexing in GSC after the update and re-check in 6-8 weeks (page 3 moves slower) | P3: =IF(LEN(O3)=0,0,IFERROR(FIND(CHAR(10),O3)-1,LEN(O3))) | Q3: To do
A4: https://www.harbourdental.example/blog/teeth-whitening-cost/ | B4: =IF(E4<21,2,3) | C4: 64 | D4: 8380 | E4: 16.8 | F4: =IFERROR(C4/D4,0) | G4: =MAX(0,ROUND(D4*'Method & Notes'!$B$12-C4,0)) | H4: Medium | I4: teeth whitening cost (pos 15.6, 3,235 impr) how much is teeth whitening (pos 16.8, 1,275 impr) teeth whitening cost australia (pos 18.0, 1,054 impr) zoom whitening price (pos 19.3, 620 impr) take home whitening kit cost (pos 20.1, 400 impr) | J4: 57 | K4: =COUNTIF('Keyword Gaps'!$A:$A,A4) | L4: A cost page that doesn't show a single price ('Contact us for current prices'), so it can't satisfy any of its price queries. It also competes with the teeth whitening service page for 'teeth whitening cost' (5,300 impressions split between the two). | M4: 1. Add chunk C1 right after the intro: price table for in-chair, Zoom and take-home whitening, plus what changes the price 2. Make this page the owner of 'teeth whitening cost': the service page links here with that anchor (chunk C2 on the service page) and drops cost from its title 3. Add an 'In-chair vs take-home: which is better value?' paragraph comparing results and price per treatment 4. Retitle to 'Teeth Whitening Cost: In-Chair, Zoom & Take-Home Prices' and show an updated date 5. Add author/dentist byline and link to the service page with anchor 'professional teeth whitening' | N4: /services/teeth-whitening/ -> anchor 'teeth whitening cost' | P4: =IF(LEN(O4)=0,0,IFERROR(FIND(CHAR(10),O4)-1,LEN(O4))) | Q4: To do
A5: https://www.harbourdental.example/services/childrens-dentistry/ | B5: =IF(E5<21,2,3) | C5: 75 | D5: 7609 | E5: 13.6 | F5: =IFERROR(C5/D5,0) | G5: =MAX(0,ROUND(D5*'Method & Notes'!$B$12-C5,0)) | H5: Low | I5: kids dentist near me (pos 13.0, 1,839 impr) child dental benefits schedule (pos 15.4, 1,580 impr) childrens dentist parramatta (pos 11.0, 1,492 impr) bulk billing kids dentist (pos 14.4, 804 impr) first dental visit age (pos 16.9, 548 impr) | J5: 55 | K5: =COUNTIF('Keyword Gaps'!$A:$A,A5) | L5: Sits at the top of page 2 (~13) for 'kids dentist near me' and 'childrens dentist parramatta', but the page never names Parramatta or mentions the Child Dental Benefits Schedule or bulk billing, which parents are clearly searching for (2,400+ impressions). | M5: 1. Add the location sentence (chunk C3) and local signals (chunk C1) to the intro 2. Add chunk C2 (Child Dental Benefits Schedule section) with chunk C4 (bulk billing) inside it 3. Add chunk C5 ('When should your child first see a dentist?') as a new H2 4. Rename the H1 to 'Children's Dentist in Parramatta' 5. Link from the homepage and from /services/emergency-dentist/ ('children's dentist') | P5: =IF(LEN(O5)=0,0,IFERROR(FIND(CHAR(10),O5)-1,LEN(O5))) | Q5: To do
A6: https://www.harbourdental.example/services/dental-crowns/ | B6: =IF(E6<21,2,3) | C6: 18 | D6: 4777 | E6: 26.4 | F6: =IFERROR(C6/D6,0) | G6: =MAX(0,ROUND(D6*'Method & Notes'!$B$12-C6,0)) | H6: Low | I6: dental crown cost (pos 26.4, 1,817 impr) porcelain crowns (pos 27.9, 653 impr) dental crowns parramatta (pos 22.1, 643 impr) crown vs filling (pos 29.6, 568 impr) | J6: 40 | K6: =COUNTIF('Keyword Gaps'!$A:$A,A6) | L6: Page 3 (pos ~26) with a 40-word page. Cost searches are half of all impressions ('dental crown cost'), and 'crown vs filling' and 'porcelain crowns' have no matching content. The page needs to become a real service page before tweaks will matter. | M6: 1. Rewrite into a full crowns page: what a crown is, when you need one, crown vs filling (chunk C4), materials, cost (chunk C1), the process, aftercare 2. Add chunk C1 (cost section) and chunk C4 (crown vs filling table) as new H2s 3. Apply the sentence edit for 'porcelain crowns' (chunk C2) and the location sentence (chunk C3) 4. Link from /services/root-canal/ ('a crown to protect the tooth') and from the homepage services block 5. Retitle to 'Dental Crowns Parramatta | Cost, Porcelain & Zirconia Crowns' | P6: =IF(LEN(O6)=0,0,IFERROR(FIND(CHAR(10),O6)-1,LEN(O6))) | Q6: To do

Sheet Keyword Gaps
A1: Page URL | B1: Keyword (ranking query) | C1: Impressions | D1: Clicks | E1: Position | F1: Status | G1: Intent | H1: In title | I1: In H1 | J1: In H2/H3 | K1: Body mentions | L1: Missing words | M1: Chunk ID | N1: Fix type | O1: Where on the page
A2: https://www.harbourdental.example/services/teeth-whitening/ | B2: teeth whitening parramatta | C2: 4360 | D2: 154 | E2: 3.3 | F2: Scattered terms | G2: Topic / modifier | H2: No | I2: No | J2: No | K2: 0 | M2: C1 | N2: Location sentence: use the phrase once in the intro and once in a heading or the title | O2: Intro paragraph (first 100 words), plus the H1 or title if it is a top query
A3: https://www.harbourdental.example/services/teeth-whitening/ | B3: teeth whitening cost | C3: 2070 | D3: 9 | E3: 12.7 | F3: Partial | G3: Cost / pricing | H3: No | I3: No | J3: No | K3: 0 | L3: cost | M3: C2 | N3: Pricing section: price range or 'from $X', what changes the cost, payment options | O3: New 'Cost' section before 'Book Your Appointment'
A4: https://www.harbourdental.example/services/teeth-whitening/ | B4: professional teeth whitening | C4: 1439 | D4: 42 | E4: 3.5 | F4: Not in headings | G4: Topic / modifier | H4: No | I4: No | J4: No | K4: 1 | M4: C3 | N4: Heading edit: work the phrase into an existing H2/H3 (and title/meta if it is the top query) | O4: Rewrite H2 'Our Whitening Treatments'
A5: https://www.harbourdental.example/services/teeth-whitening/ | B5: how long does teeth whitening last | C5: 994 | D5: 13 | E5: 7 | F5: Partial | G5: Question | H5: No | I5: No | J5: No | K5: 0 | L5: long, last | M5: C4 | N5: FAQ: the question as an H3 + a 40-60 word direct answer | O5: New FAQ section before 'Book Your Appointment'
A6: https://www.harbourdental.example/services/teeth-whitening/ | B6: zoom teeth whitening | C6: 796 | D6: 19 | E6: 4.8 | F6: Partial | G6: Topic / modifier | H6: No | I6: No | J6: No | K6: 0 | L6: zoom | M6: C5 | N6: New H2/H3 section (80-150 words) | O6: New H2 section before 'Book Your Appointment'
A7: https://www.harbourdental.example/services/teeth-whitening/ | B7: is teeth whitening safe | C7: 615 | D7: 6 | E7: 7.6 | F7: Partial | G7: Question | H7: No | I7: No | J7: No | K7: 0 | L7: safe | M7: C4 | N7: FAQ: the question as an H3 + a 40-60 word direct answer | O7: New FAQ section before 'Book Your Appointment'
A8: https://www.harbourdental.example/services/teeth-whitening/ | B8: in chair teeth whitening | C8: 410 | D8: 10 | E8: 4.4 | F8: Scattered terms | G8: Topic / modifier | H8: No | I8: No | J8: No | K8: 0 | M8: C6 | N8: Sentence edit: add the exact phrase naturally to an existing paragraph | O8: An existing paragraph under 'Our Whitening Treatments'
A9: https://www.harbourdental.example/services/invisalign/ | B9: invisalign cost | C9: 3226 | D9: 27 | E9: 9.6 | F9: Partial | G9: Cost / pricing | H9: No | I9: No | J9: No | K9: 0 | L9: cost | M9: C1 | N9: Pricing section: price range or 'from $X', what changes the cost, payment options | O9: New 'Cost' section before the final call to action
A10: https://www.harbourdental.example/services/invisalign/ | B10: invisalign parramatta | C10: 1938 | D10: 47 | E10: 5.1 | F10: Scattered terms | G10: Topic / modifier | H10: No | I10: No | J10: No | K10: 0 | M10: C2 | N10: Sentence edit: add the exact phrase naturally to an existing paragraph | O10: An existing paragraph under 'What is Invisalign?'
A11: https://www.harbourdental.example/services/invisalign/ | B11: invisalign provider near me | C11: 915 | D11: 14 | E11: 6.5 | F11: Not in headings | G11: Local (near me) | H11: No | I11: No | J11: No | K11: 1 | M11: C3 | N11: Local signals: suburb/area names, address, map, LocalBusiness schema (never add 'near me' literally) | O11: Intro paragraph (first 100 words), plus the H1 or title if it is a top query
A12: https://www.harbourdental.example/services/invisalign/ | B12: how long does invisalign take | C12: 715 | D12: 4 | E12: 10.6 | F12: Missing | G12: Question | H12: No | I12: No | J12: No | K12: 0 | L12: long, take | M12: C4 | N12: FAQ: the question as an H3 + a 40-60 word direct answer | O12: New FAQ section before the final call to action
A13: https://www.harbourdental.example/services/invisalign/ | B13: invisalign payment plans | C13: 560 | D13: 3 | E13: 10.2 | F13: Partial | G13: Cost / pricing | H13: No | I13: No | J13: No | K13: 0 | L13: payment | M13: C1 | N13: Pricing section: price range or 'from $X', what changes the cost, payment options | O13: New 'Cost' section before the final call to action
A14: https://www.harbourdental.example/blog/invisalign-vs-braces/ | B14: invisalign vs braces cost | C14: 1109 | D14: 6 | E14: 10.7 | F14: Partial | G14: Comparison | H14: No | I14: No | J14: No | K14: 0 | L14: cost | M14: C1 | N14: Comparison table + 2-3 sentence verdict | O14: Right after the intro (comparison table first)
A15: https://www.harbourdental.example/blog/invisalign-vs-braces/ | B15: braces or invisalign for adults | C15: 694 | D15: 3 | E15: 10.3 | F15: Partial | G15: Comparison | H15: No | I15: No | J15: No | K15: 0 | L15: adults | M15: C1 | N15: Comparison table + 2-3 sentence verdict | O15: Right after the intro (comparison table first)
A16: https://www.harbourdental.example/blog/invisalign-vs-braces/ | B16: invisalign vs braces pros and cons | C16: 579 | D16: 3 | E16: 10.6 | F16: Partial | G16: Comparison | H16: No | I16: No | J16: No | K16: 0 | L16: pros, cons | M16: C1 | N16: Comparison table + 2-3 sentence verdict | O16: Right after the intro (comparison table first)
A17: https://www.harbourdental.example/blog/invisalign-vs-braces/ | B17: which is faster invisalign or braces | C17: 393 | D17: 2 | E17: 11.5 | F17: Partial | G17: Comparison | H17: No | I17: No | J17: No | K17: 0 | L17: faster | M17: C1 | N17: Comparison table + 2-3 sentence verdict | O17: Right after the intro (comparison table first)
A18: https://www.harbourdental.example/blog/how-long-do-dental-implants-last/ | B18: dental implant lifespan | C18: 991 | D18: 11 | E18: 8.9 | F18: Partial | G18: Topic / modifier | H18: No | I18: No | J18: No | K18: 0 | L18: lifespan | M18: C1 | N18: New H2/H3 section (80-150 words) | O18: New H2 section before the final call to action
A19: https://www.harbourdental.example/blog/how-long-do-dental-implants-last/ | B19: do dental implants last forever | C19: 682 | D19: 9 | E19: 8.4 | F19: Partial | G19: Question | H19: No | I19: No | J19: No | K19: 0 | L19: forever | M19: C2 | N19: FAQ: the question as an H3 + a 40-60 word direct answer | O19: New FAQ section before the final call to action
A20: https://www.harbourdental.example/blog/how-long-do-dental-implants-last/ | B20: dental implant failure signs | C20: 501 | D20: 3 | E20: 14.9 | F20: Partial | G20: Topic / modifier | H20: No | I20: No | J20: No | K20: 0 | L20: failure, signs | M20: C3 | N20: New H2/H3 section (80-150 words) | O20: New H2 section before the final call to action
A21: https://www.harbourdental.example/blog/how-long-do-dental-implants-last/ | B21: implant vs bridge longevity | C21: 280 | D21: 1 | E21: 14.9 | F21: Missing | G21: Comparison | H21: No | I21: No | J21: No | K21: 0 | L21: bridge, longevity | M21: C4 | N21: Comparison table + 2-3 sentence verdict | O21: New comparison section before the final call to action
A22: https://www.harbourdental.example/services/dental-implants/ | B22: dental implants cost | C22: 4035 | D22: 35 | E22: 18.1 | F22: Partial | G22: Cost / pricing | H22: No | I22: No | J22: No | K22: 0 | L22: cost | M22: C1 | N22: Pricing section: price range or 'from $X', what changes the cost, payment options | O22: New 'Cost' section before the final call to action
A23: https://www.harbourdental.example/services/dental-implants/ | B23: all on 4 dental implants | C23: 1517 | D23: 11 | E23: 19.5 | F23: Partial | G23: Topic / modifier | H23: No | I23: No | J23: No | K23: 0 | L23: all, 4 | M23: C2 | N23: New H2/H3 section (80-150 words) | O23: New H2 section before the final call to action
... A33: https://www.harbourdental.example/blog/teeth-whitening-cost/ | B33: zoom whitening price | C33: 620 | D33: 4 | E33: 19.3 | F33: Partial | G33: Cost / pricing | H33: No | I33: No | J33: No | K33: 0 | L33: zoom | M33: C1 | N33: Pricing section: price range or 'from $X', what changes the cost, payment options | O33: Right after the intro - searchers on this page want the price first
A34: https://www.harbourdental.example/blog/teeth-whitening-cost/ | B34: take home whitening kit cost | C34: 400 | D34: 2 | E34: 20.1 | F34: Scattered terms | G34: Cost / pricing | H34: No | I34: No | J34: No | K34: 0 | M34: C1 | N34: Pricing section: price range or 'from $X', what changes the cost, payment options | O34: Right after the intro - searchers on this page want the price first
A35: https://www.harbourdental.example/services/childrens-dentistry/ | B35: kids dentist near me | C35: 1839 | D35: 19 | E35: 13 | F35: Scattered terms | G35: Local (near me) | H35: No | I35: No | J35: No | K35: 0 | M35: C1 | N35: Local signals: suburb/area names, address, map, LocalBusiness schema (never add 'near me' literally) | O35: Intro paragraph (first 100 words), plus the H1 or title if it is a top query
A36: https://www.harbourdental.example/services/childrens-dentistry/ | B36: child dental benefits schedule | C36: 1580 | D36: 13 | E36: 15.4 | F36: Partial | G36: Topic / modifier | H36: No | I36: No | J36: No | K36: 0 | L36: benefits, schedule | M36: C2 | N36: New H2/H3 section (80-150 words) | O36: New H2 section before the final call to action
A37: https://www.harbourdental.example/services/childrens-dentistry/ | B37: childrens dentist parramatta | C37: 1492 | D37: 18 | E37: 11 | F37: Scattered terms | G37: Topic / modifier | H37: No | I37: No | J37: No | K37: 0 | M37: C3 | N37: Location sentence: use the phrase once in the intro and once in a heading or the title | O37: Intro paragraph (first 100 words), plus the H1 or title if it is a top query
A38: https://www.harbourdental.example/services/childrens-dentistry/ | B38: bulk billing kids dentist | C38: 804 | D38: 7 | E38: 14.4 | F38: Partial | G38: Cost / pricing | H38: No | I38: No | J38: No | K38: 0 | L38: bulk, billing | M38: C4 | N38: Pricing section: price range or 'from $X', what changes the cost, payment options | O38: New 'Cost' section before the final call to action
A39: https://www.harbourdental.example/services/childrens-dentistry/ | B39: first dental visit age | C39: 548 | D39: 5 | E39: 16.9 | F39: Partial | G39: Topic / modifier | H39: No | I39: No | J39: No | K39: 0 | L39: first, visit | M39: C5 | N39: New H2/H3 section (80-150 words) | O39: New H2 section before the final call to action
A40: https://www.harbourdental.example/services/dental-crowns/ | B40: dental crown cost | C40: 1817 | D40: 6 | E40: 26.4 | F40: Partial | G40: Cost / pricing | H40: No | I40: No | J40: No | K40: 0 | L40: cost | M40: C1 | N40: Pricing section: price range or 'from $X', what changes the cost, payment options | O40: New 'Cost' section before the final call to action
A41: https://www.harbourdental.example/services/dental-crowns/ | B41: porcelain crowns | C41: 653 | D41: 3 | E41: 27.9 | F41: Scattered terms | G41: Topic / modifier | H41: No | I41: No | J41: No | K41: 0 | M41: C2 | N41: Sentence edit: add the exact phrase naturally to an existing paragraph | O41: An existing paragraph under 'What is a crown?'
A42: https://www.harbourdental.example/services/dental-crowns/ | B42: dental crowns parramatta | C42: 643 | D42: 3 | E42: 22.1 | F42: Partial | G42: Topic / modifier | H42: No | I42: No | J42: No | K42: 0 | L42: parramatta | M42: C3 | N42: Location sentence: use the phrase once in the intro and once in a heading or the title | O42: Intro paragraph (first 100 words), plus the H1 or title if it is a top query
A43: https://www.harbourdental.example/services/dental-crowns/ | B43: crown vs filling | C43: 568 | D43: 2 | E43: 29.6 | F43: Partial | G43: Comparison | H43: No | I43: No | J43: No | K43: 0 | L43: filling | M43: C4 | N43: Comparison table + 2-3 sentence verdict | O43: New comparison section before the final call to action

Sheet Content Chunks
A1: # | B1: Page URL | C1: Chunk ID | D1: Target keywords | E1: Keyword impressions | F1: Chunk type | G1: Where to add it | H1: Heading | I1: Content to add (ready to paste) | J1: Words | K1: Check before publishing | L1: Status
A2: 1 | B2: https://www.harbourdental.example/services/teeth-whitening/ | C2: C1 | D2: teeth whitening parramatta | E2: 4360 | F2: Location sentence | G2: First sentence of the intro + H1 | I2: Looking for teeth whitening in Parramatta? Our team at Harbour Dental provides professional whitening for adults who want to lift stains from coffee, tea, red wine and smoking. | J2: =IF(OR(LEN(TRIM(I2))=0,I2="(not written yet)"),0,LEN(TRIM(I2))-LEN(SUBSTITUTE(TRIM(I2)," ",""))+1) | L2: To do
A3: 2 | B3: https://www.harbourdental.example/services/teeth-whitening/ | C3: C2 | D3: teeth whitening cost | E3: 2070 | F3: Teaser + link (another page owns this query) | G3: Short paragraph before 'Book Your Appointment' | H3: How much does teeth whitening cost? | I3: The cost of teeth whitening depends on whether you choose an in-chair session or a take-home kit. In-chair whitening starts from [price] and take-home kits from [price]. See our full teeth whitening cost guide for a breakdown of every option. | J3: =IF(OR(LEN(TRIM(I3))=0,I3="(not written yet)"),0,LEN(TRIM(I3))-LEN(SUBSTITUTE(TRIM(I3)," ",""))+1) | K3: Link 'teeth whitening cost guide' to /blog/teeth-whitening-cost/. Confirm both prices. Don't add a full price table here - the cost page owns this query. | L3: To do
A4: 3 | B4: https://www.harbourdental.example/services/teeth-whitening/ | C4: C4 | D4: how long does teeth whitening last, is teeth whitening safe | E4: 1609 | F4: FAQ | G4: New FAQ section before 'Book Your Appointment' | H4: Teeth whitening FAQs | I4: Q: How long does teeth whitening last? A: Professional whitening usually lasts from [6 months to 2 years]. How long yours lasts depends on what you eat and drink, whether you smoke and how well you care for your teeth. Using your take-home trays for a quick top-up every few months keeps your smile bright for longer. Q: Is teeth whitening safe? A: Yes. Teeth whitening is safe when it's done or supervised by a dentist. We check your teeth and gums first, protect your gums during treatment and use professional gels at the right strength. Some people feel temporary sensitivity for a day or two, which settles on its own. | J4: =IF(OR(LEN(TRIM(I4))=0,I4="(not written yet)"),0,LEN(TRIM(I4))-LEN(SUBSTITUTE(TRIM(I4)," ",""))+1) | K4: Confirm the typical result duration the clinic quotes. | L4: To do
A5: 4 | B5: https://www.harbourdental.example/services/teeth-whitening/ | C5: C3 | D5: professional teeth whitening | E5: 1439 | F5: Heading edit | G5: H2 'Our Whitening Treatments' | H5: Professional Teeth Whitening Treatments | I5: H2 'Our Whitening Treatments' -> 'Professional Teeth Whitening Treatments' | J5: =IF(OR(LEN(TRIM(I5))=0,I5="(not written yet)"),0,LEN(TRIM(I5))-LEN(SUBSTITUTE(TRIM(I5)," ",""))+1) | L5: To do
A6: 5 | B6: https://www.harbourdental.example/services/teeth-whitening/ | C6: C5 | D6: zoom teeth whitening | E6: 796 | F6: New H3 section | G6: New H3 under 'Professional Teeth Whitening Treatments', after the in-chair paragraph | H6: Zoom teeth whitening | I6: Zoom teeth whitening is a popular in-chair system that uses a professional whitening gel activated by a special light. [It is one of the in-chair options we offer at our Parramatta clinic.] A session takes about an hour, and many patients see their teeth several shades lighter by the time they leave. We'll check whether Zoom or another in-chair option suits your teeth during your consultation. | J6: =IF(OR(LEN(TRIM(I6))=0,I6="(not written yet)"),0,LEN(TRIM(I6))-LEN(SUBSTITUTE(TRIM(I6)," ",""))+1) | K6: Only publish if the clinic actually offers Zoom. If not, replace with a sentence explaining the in-chair system it does use. | L6: To do
A7: 6 | B7: https://www.harbourdental.example/services/teeth-whitening/ | C7: C6 | D7: in chair teeth whitening | E7: 410 | F7: Sentence edit | G7: First sentence under 'Professional Teeth Whitening Treatments' | I7: Before: "We offer an in-chair whitening session that takes about one hour." After: "Our in-chair teeth whitening session takes about one hour." | J7: =IF(OR(LEN(TRIM(I7))=0,I7="(not written yet)"),0,LEN(TRIM(I7))-LEN(SUBSTITUTE(TRIM(I7)," ",""))+1) | L7: To do
A8: 7 | B8: https://www.harbourdental.example/services/invisalign/ | C8: C1 | D8: invisalign cost, invisalign payment plans | E8: 3786 | F8: Pricing section | G8: New H2 after 'Who is Invisalign suitable for?' | H8: How much does Invisalign cost? | I8: Invisalign at our Parramatta clinic typically costs [price range], depending on how complex your case is. We confirm your exact price after your 3D scan, so there are no surprises. What affects the cost: - How far your teeth need to move - The number of aligners in your plan - Whether you need refinement aligners at the end - Retainers to hold your new smile in place Invisalign payment plans let you spread the cost over [term] from [$X per week]. Ask about health fund rebates for orthodontic cover. | J8: =IF(OR(LEN(TRIM(I8))=0,I8="(not written yet)"),0,LEN(TRIM(I8))-LEN(SUBSTITUTE(TRIM(I8)," ",""))+1) | K8: Confirm price range, payment-plan term and weekly amount, and whether health fund rebates apply. | L8: To do
A9: 8 | B9: https://www.harbourdental.example/services/invisalign/ | C9: C2 | D9: invisalign parramatta | E9: 1938 | F9: Sentence edit | G9: Last sentence of the page / intro | I9: Before: "Harbour Dental is an Invisalign provider in Parramatta." After (move to the intro): "Harbour Dental is a certified provider of Invisalign in Parramatta, so you can start your treatment close to home." | J9: =IF(OR(LEN(TRIM(I9))=0,I9="(not written yet)"),0,LEN(TRIM(I9))-LEN(SUBSTITUTE(TRIM(I9)," ",""))+1) | K9: Confirm the provider status wording. | L9: To do
A10: 9 | B10: https://www.harbourdental.example/services/invisalign/ | C10: C3 | D10: invisalign provider near me | E10: 915 | F10: Local signals | G10: Intro + contact block | I10: - Name Parramatta and nearby suburbs in the intro: "...for patients in Parramatta, Westmead, Harris Park and North Parramatta" - Add the clinic address, opening hours and a map embed above the final call to action - Add Dentist (LocalBusiness) schema with address, geo and areaServed - Link to the Google Business Profile and show the Invisalign provider badge if the clinic has one | J10: =IF(OR(LEN(TRIM(I10))=0,I10="(not written yet)"),0,LEN(TRIM(I10))-LEN(SUBSTITUTE(TRIM(I10)," ",""))+1) | K10: Confirm the suburbs served. | L10: To do
A11: 10 | B11: https://www.harbourdental.example/services/invisalign/ | C11: C4 | D11: how long does invisalign take | E11: 715 | F11: FAQ | G11: New FAQ section before the final call to action | H11: Invisalign FAQs | I11: Q: How long does Invisalign take? A: Most Invisalign treatments take between [6 and 18 months], and simple cases can be quicker. How long yours takes depends on how much your teeth need to move and on wearing your aligners for 20-22 hours a day. Your 3D scan plan shows your expected timeline before you start. | J11: =IF(OR(LEN(TRIM(I11))=0,I11="(not written yet)"),0,LEN(TRIM(I11))-LEN(SUBSTITUTE(TRIM(I11)," ",""))+1) | K11: Confirm the typical treatment range the clinic quotes. | L11: To do
A12: 11 | B12: https://www.harbourdental.example/blog/invisalign-vs-braces/ | C12: C1 | D12: invisalign vs braces cost, braces or invisalign for adults, invisalign vs braces pros and cons, which is faster invisalign or braces | E12: 2775 | F12: Comparison table + verdict | G12: Right after the intro | H12: Invisalign vs braces at a glance | I12: | | Invisalign | Braces | | Cost | [range] | [range] | | Treatment time | Typically [x-y] months | Typically [x-y] months | | Looks | Nearly invisible | Visible brackets and wire | | Comfort | Smooth plastic, no wires | Brackets can rub at first | | Eating | Remove aligners to eat | Avoid hard and sticky foods | | Best for | Mild to moderate cases, adults and teens who'll wear them 22 hours a day | Complex cases, or anyone who'd forget to wear aligners | Pros and cons in short: Invisalign wins on looks and comfort but only works if you wear it. Braces work around the clock and suit complex bites, but they're more visible. Which is faster, Invisalign or braces? For mild cases Invisalign can be as fast or faster; for complex movements braces are often quicker. Braces or Invisalign for adults? Most adults choose Invisalign because it's discreet, but braces remain the better choice for severe crowding or bite problems. | J12: =IF(OR(LEN(TRIM(I12))=0,I12="(not written yet)"),0,LEN(TRIM(I12))-LEN(SUBSTITUTE(TRIM(I12)," ",""))+1) | K12: Fill in cost and treatment-time ranges from the clinic's real fees. | L12: To do
A13: 12 | B13: https://www.harbourdental.example/blog/how-long-do-dental-implants-last/ | C13: C1 | D13: dental implant lifespan | E13: 991 | F13: New H2 section | G13: New H2 straight after the intro | H13: Dental implant lifespan: post vs crown | I13: A dental implant has two parts with different lifespans. The titanium post fused to your jaw is designed to be permanent and, with good care, often lasts for decades or a lifetime. The crown on top takes the daily wear of chewing, so it usually lasts 10 to 15 years before it may need replacing. When people ask about dental implant lifespan, the crown is usually the part that needs attention first. | J13: =IF(OR(LEN(TRIM(I13))=0,I13="(not written yet)"),0,LEN(TRIM(I13))-LEN(SUBSTITUTE(TRIM(I13)," ",""))+1) | L13: To do
A14: 13 | B14: https://www.harbourdental.example/blog/how-long-do-dental-implants-last/ | C14: C2 | D14: do dental implants last forever | E14: 682 | F14: FAQ | G14: New FAQ section before the conclusion | H14: Dental implant FAQs | I14: Q: Do dental implants last forever? A: The implant post can last a lifetime, but the whole implant isn't maintenance-free. The crown usually needs replacing after 10 to 15 years, and gum disease, smoking or teeth grinding can shorten the life of the post. Brushing, flossing and regular check-ups give your implant the best chance of lasting. | J14: =IF(OR(LEN(TRIM(I14))=0,I14="(not written yet)"),0,LEN(TRIM(I14))-LEN(SUBSTITUTE(TRIM(I14)," ",""))+1) | L14: To do
A15: 14 | B15: https://www.harbourdental.example/blog/how-long-do-dental-implants-last/ | C15: C3 | D15: dental implant failure signs | E15: 501 | F15: List section | G15: New H2 after 'What affects how long an implant lasts' | H15: Signs your dental implant may be failing | I15: See your dentist promptly if you notice any of these dental implant failure signs: - The implant or crown feels loose or moves when you bite - Pain or throbbing around the implant that doesn't settle - Swollen, red or bleeding gums around the implant - Gum shrinking back so the metal post becomes visible - Difficulty or discomfort when chewing Caught early, many implant problems can be treated without losing the implant. | J15: =IF(OR(LEN(TRIM(I15))=0,I15="(not written yet)"),0,LEN(TRIM(I15))-LEN(SUBSTITUTE(TRIM(I15)," ",""))+1) | L15: To do
A16: 15 | B16: https://www.harbourdental.example/blog/how-long-do-dental-implants-last/ | C16: C4 | D16: implant vs bridge longevity | E16: 280 | F16: Comparison table + verdict | G16: New H2 before 'Caring for your implant' | H16: Implant vs bridge: which lasts longer? | I16: | | Dental implant | Dental bridge | | Typical lifespan | Post: decades; crown: 10-15 years | Typically [10-15] years | | Effect on nearby teeth | None - stands alone | Neighbouring teeth are filed down to hold it | | Jawbone | Helps preserve bone | Bone can shrink under the gap | On implant vs bridge longevity, an implant usually wins because the post can last a lifetime and it doesn't rely on the teeth next to it. A bridge can be a good, quicker option when implants aren't suitable. | J16: =IF(OR(LEN(TRIM(I16))=0,I16="(not written yet)"),0,LEN(TRIM(I16))-LEN(SUBSTITUTE(TRIM(I16)," ",""))+1) | K16: Confirm the bridge lifespan range the clinic quotes. | L16: To do
A17: 16 | B17: https://www.harbourdental.example/services/dental-implants/ | C17: C1 | D17: dental implants cost, dental implants payment plan | E17: 4402 | F17: Pricing section | G17: New H2 right after the intro | H17: How much do dental implants cost? | I17: A single dental implant at our Parramatta clinic typically costs [price range], including the implant post, abutment and crown. Your exact quote depends on your 3D scan. What affects dental implants cost: - How many teeth you're replacing - Whether you need a bone graft or sinus lift first - The type of implant and crown material - Single implants vs full-arch options like All-on-4 A dental implants payment plan lets you spread the cost from [$X per week]. We give you a written, itemised quote before any treatment starts. | J17: =IF(OR(LEN(TRIM(I17))=0,I17="(not written yet)"),0,LEN(TRIM(I17))-LEN(SUBSTITUTE(TRIM(I17)," ",""))+1) | K17: Confirm price range, what's included and payment-plan terms. | L17: To do
A18: 17 | B18: https://www.harbourdental.example/services/dental-implants/ | C18: C2 | D18: all on 4 dental implants | E18: 1517 | F18: New H2 section | G18: New H2 after 'The implant process' | H18: All-on-4 dental implants | I18: All-on-4 dental implants replace a full arch of teeth using just four implants. A fixed bridge of new teeth is attached to the implants, often on the same day as surgery [confirm], so you don't go without teeth while you heal. All-on-4 suits people who have lost most of their teeth or who are tired of loose dentures. It also often avoids bone grafting because the implants are angled to use the strongest bone. | J18: =IF(OR(LEN(TRIM(I18))=0,I18="(not written yet)"),0,LEN(TRIM(I18))-LEN(SUBSTITUTE(TRIM(I18)," ",""))+1) | K18: Only publish if the clinic offers All-on-4; confirm the same-day teeth claim. | L18: To do
A19: 18 | B19: https://www.harbourdental.example/services/dental-implants/ | C19: C3 | D19: single tooth implant | E19: 947 | F19: New H2 section | G19: New H2 before 'All-on-4 dental implants' | H19: Single tooth implants | I19: A single tooth implant replaces one missing tooth without touching the teeth on either side. A titanium post is placed where the root used to be, and once it has bonded with the bone a custom crown is fitted to match your natural teeth. It looks, feels and works like a real tooth, and because it stands on its own, you clean it just like the rest of your teeth. | J19: =IF(OR(LEN(TRIM(I19))=0,I19="(not written yet)"),0,LEN(TRIM(I19))-LEN(SUBSTITUTE(TRIM(I19)," ",""))+1) | L19: To do
A20: 19 | B20: https://www.harbourdental.example/services/dental-implants/ | C20: C4 | D20: are dental implants painful | E20: 540 | F20: FAQ | G20: New FAQ section before 'Why choose Harbour Dental' | H20: Dental implant FAQs | I20: Q: Are dental implants painful? A: Most patients say getting a dental implant is less painful than they expected. The area is fully numbed with local anaesthetic, so you shouldn't feel pain during the procedure. Afterwards you may have some soreness and swelling for a few days, which over-the-counter pain relief usually manages. Sedation is available if you're nervous [confirm]. | J20: =IF(OR(LEN(TRIM(I20))=0,I20="(not written yet)"),0,LEN(TRIM(I20))-LEN(SUBSTITUTE(TRIM(I20)," ",""))+1) | K20: Confirm sedation is offered for implant surgery. | L20: To do
A21: 20 | B21: https://www.harbourdental.example/services/root-canal/ | C21: C1 | D21: root canal cost | E21: 2228 | F21: Pricing section | G21: New H2 after 'What happens during treatment' | H21: How much does a root canal cost? | I21: Root canal cost at our Parramatta clinic typically ranges from [price range], depending on the tooth. Front teeth have one canal and cost less; molars have three or four canals and take longer. What affects the price: - Which tooth needs treatment (front, premolar or molar) - How many canals need cleaning - Whether you need a crown afterwards - Whether the tooth has had a root canal before Your health fund may cover part of the cost under major dental. Payment plans are available [confirm]. | J21: =IF(OR(LEN(TRIM(I21))=0,I21="(not written yet)"),0,LEN(TRIM(I21))-LEN(SUBSTITUTE(TRIM(I21)," ",""))+1) | K21: Confirm price ranges and payment plans. | L21: To do
A22: 21 | B22: https://www.harbourdental.example/services/root-canal/ | C22: C2 | D22: does a root canal hurt | E22: 1138 | F22: FAQ | G22: New FAQ section before the final call to action | H22: Root canal FAQs | I22: Q: Does a root canal hurt? A: A root canal shouldn't hurt more than a normal filling. Your dentist numbs the tooth completely before starting, and the treatment removes the infection that was causing your pain. Expect some tenderness for a few days afterwards, which usually settles with over-the-counter pain relief. | J22: =IF(OR(LEN(TRIM(I22))=0,I22="(not written yet)"),0,LEN(TRIM(I22))-LEN(SUBSTITUTE(TRIM(I22)," ",""))+1) | L22: To do
A23: 22 | B23: https://www.harbourdental.example/services/root-canal/ | C23: C3 | D23: root canal parramatta | E23: 1029 | F23: Location sentence | G23: Intro + H1 | H23: Root Canal Treatment in Parramatta | I23: Our Parramatta dentists provide gentle root canal treatment to save infected or badly damaged teeth, with same-week appointments for patients in pain [confirm]. | J23: =IF(OR(LEN(TRIM(I23))=0,I23="(not written yet)"),0,LEN(TRIM(I23))-LEN(SUBSTITUTE(TRIM(I23)," ",""))+1) | K23: Use 'Root Canal Treatment in Parramatta' as the new H1. Confirm same-week appointments. | L23: To do
A24: 23 | B24: https://www.harbourdental.example/services/root-canal/ | C24: C4 | D24: root canal recovery time | E24: 801 | F24: New H2 section | G24: New H2 after the cost section | H24: Root canal recovery time | I24: Most people are back to normal activities the same day or the next day. Root canal recovery time is usually a few days of mild tenderness while the area around the tooth settles. Chew on the other side until your permanent filling or crown is fitted, keep brushing and flossing as usual, and call us if pain gets worse after three days or you notice swelling. | J24: =IF(OR(LEN(TRIM(I24))=0,I24="(not written yet)"),0,LEN(TRIM(I24))-LEN(SUBSTITUTE(TRIM(I24)," ",""))+1) | L24: To do
A25: 24 | B25: https://www.harbourdental.example/blog/teeth-whitening-cost/ | C25: C1 | D25: how much is teeth whitening, teeth whitening cost australia, zoom whitening price, take home whitening kit cost | E25: 3349 | F25: Pricing table | G25: Right after the intro | H25: How much is teeth whitening? | I25: Here's what professional teeth whitening costs at Harbour Dental: | Treatment | Price | Time | Best for | | In-chair whitening | [price] | About 1 hour | Fast results for an event | | Zoom whitening | [price] | About 1 hour | [confirm offered] | | Take-home whitening kit | [price] | 2 weeks | Gradual results, top-ups | | In-chair + take-home combo | [price] | 1 hour + top-ups | Longest-lasting results | Across Australia, teeth whitening cost varies with the treatment type and the clinic. A dentist-supervised take-home whitening kit costs less than an in-chair session but takes longer. Zoom whitening price is usually at the top of the range because of the light-activated system. | J25: =IF(OR(LEN(TRIM(I25))=0,I25="(not written yet)"),0,LEN(TRIM(I25))-LEN(SUBSTITUTE(TRIM(I25)," ",""))+1) | K25: Fill in every price. Remove the Zoom row if the clinic doesn't offer it. | L25: To do
A26: 25 | B26: https://www.harbourdental.example/services/childrens-dentistry/ | C26: C1 | D26: kids dentist near me | E26: 1839 | F26: Local signals | G26: Intro + contact block | I26: - Intro: name Parramatta and nearby suburbs families come from - Add parking/pram access and the nearest station to the contact block - Add Dentist schema with address, opening hours and areaServed - Show Google reviews from parents (link to the Business Profile) | J26: =IF(OR(LEN(TRIM(I26))=0,I26="(not written yet)"),0,LEN(TRIM(I26))-LEN(SUBSTITUTE(TRIM(I26)," ",""))+1) | K26: Confirm suburbs and parking details. | L26: To do
A27: 26 | B27: https://www.harbourdental.example/services/childrens-dentistry/ | C27: C2 | D27: child dental benefits schedule | E27: 1580 | F27: New H2 section | G27: New H2 after 'Services for kids' | H27: Child Dental Benefits Schedule (CDBS) | I27: We [accept / bulk bill] the Child Dental Benefits Schedule, a Medicare program that helps eligible families pay for their children's basic dental care. If your child is eligible, the CDBS can cover check-ups, cleans, fillings and more up to a set amount over two calendar years. Bring your Medicare card to your appointment and we'll check your child's balance for you. | J27: =IF(OR(LEN(TRIM(I27))=0,I27="(not written yet)"),0,LEN(TRIM(I27))-LEN(SUBSTITUTE(TRIM(I27)," ",""))+1) | K27: Confirm whether the clinic bulk bills CDBS and check current eligibility rules and cap on servicesaustralia.gov.au before publishing. | L27: To do
A28: 27 | B28: https://www.harbourdental.example/services/childrens-dentistry/ | C28: C3 | D28: childrens dentist parramatta | E28: 1492 | F28: Location sentence | G28: Intro + H1 | H28: Children's Dentist in Parramatta | I28: Looking for a friendly children's dentist in Parramatta? Our team loves looking after kids and helping them feel relaxed at every visit. | J28: =IF(OR(LEN(TRIM(I28))=0,I28="(not written yet)"),0,LEN(TRIM(I28))-LEN(SUBSTITUTE(TRIM(I28)," ",""))+1) | K28: Use 'Children's Dentist in Parramatta' as the new H1. | L28: To do
A29: 28 | B29: https://www.harbourdental.example/services/childrens-dentistry/ | C29: C4 | D29: bulk billing kids dentist | E29: 804 | F29: Sentence (inside the CDBS section) | G29: Last sentence of the CDBS section (chunk C2) | I29: As a bulk billing kids dentist for eligible CDBS patients, we bill Medicare directly, so there's nothing to pay on the day for covered treatment. | J29: =IF(OR(LEN(TRIM(I29))=0,I29="(not written yet)"),0,LEN(TRIM(I29))-LEN(SUBSTITUTE(TRIM(I29)," ",""))+1) | K29: Only publish if the clinic bulk bills under CDBS. | L29: To do
A30: 29 | B30: https://www.harbourdental.example/services/childrens-dentistry/ | C30: C5 | D30: first dental visit age | E30: 548 | F30: New H2 section | G30: New H2 before 'Services for kids' | H30: When should your child first see a dentist? | I30: The recommended first dental visit age is when your child's first tooth appears, or by their first birthday. Early visits are short and gentle: we count teeth, check for early decay and show you how to brush little teeth. Starting young helps children see the dentist as a normal, friendly part of life. | J30: =IF(OR(LEN(TRIM(I30))=0,I30="(not written yet)"),0,LEN(TRIM(I30))-LEN(SUBSTITUTE(TRIM(I30)," ",""))+1) | K30: Check the wording against current Australian Dental Association guidance. | L30: To do
A31: 30 | B31: https://www.harbourdental.example/services/dental-crowns/ | C31: C1 | D31: dental crown cost | E31: 1817 | F31: Pricing section | G31: New H2 after 'What is a crown?' | H31: How much does a dental crown cost? | I31: Dental crown cost at our Parramatta clinic typically ranges from [price range] per tooth. The main things that change the price are: - The material: porcelain, zirconia or gold - Whether the tooth needs a root canal or core build-up first - Same-day vs lab-made crowns [confirm] Most health funds with major dental cover pay part of the cost, and payment plans are available [confirm]. | J31: =IF(OR(LEN(TRIM(I31))=0,I31="(not written yet)"),0,LEN(TRIM(I31))-LEN(SUBSTITUTE(TRIM(I31)," ",""))+1) | K31: Confirm prices, same-day crowns and payment plans. | L31: To do
A32: 31 | B32: https://www.harbourdental.example/services/dental-crowns/ | C32: C2 | D32: porcelain crowns | E32: 653 | F32: Sentence edit | G32: Under 'What is a crown?' | I32: Before: "Crowns are made from porcelain, zirconia or gold and are custom-made to match your teeth." After: "We offer porcelain crowns, zirconia crowns and gold crowns, each custom-made to match your teeth. Porcelain crowns are the most natural-looking choice for front teeth." | J32: =IF(OR(LEN(TRIM(I32))=0,I32="(not written yet)"),0,LEN(TRIM(I32))-LEN(SUBSTITUTE(TRIM(I32)," ",""))+1) | L32: To do
A33: 32 | B33: https://www.harbourdental.example/services/dental-crowns/ | C33: C3 | D33: dental crowns parramatta | E33: 643 | F33: Location sentence | G33: Intro + H1 | H33: Dental Crowns in Parramatta | I33: Our dentists provide custom dental crowns in Parramatta to restore cracked, worn or heavily filled teeth so they look and work like new. | J33: =IF(OR(LEN(TRIM(I33))=0,I33="(not written yet)"),0,LEN(TRIM(I33))-LEN(SUBSTITUTE(TRIM(I33)," ",""))+1) | K33: Use 'Dental Crowns in Parramatta' as the new H1. | L33: To do
A34: 33 | B34: https://www.harbourdental.example/services/dental-crowns/ | C34: C4 | D34: crown vs filling | E34: 568 | F34: Comparison table + verdict | G34: New H2 after the cost section | H34: Crown vs filling: which do you need? | I34: | | Filling | Crown | | Best for | Small to medium cavities | Large damage, cracks, after root canal | | How much tooth is kept | Most of the tooth | Tooth is shaped to fit a cap | | Visits | Usually one | One or two | | Typical lifespan | [range] | [range] | Crown vs filling comes down to how much healthy tooth is left. If a cavity is small, a filling is simpler and cheaper. If more than about half the tooth is damaged, a crown protects it from cracking. | J34: =IF(OR(LEN(TRIM(I34))=0,I34="(not written yet)"),0,LEN(TRIM(I34))-LEN(SUBSTITUTE(TRIM(I34)," ",""))+1) | K34: Confirm lifespan ranges. | L34: To do

Sheet Internal Links
A1: Page to boost (link target) | B1: Add a link FROM this page | C1: Source page clicks | D1: Suggested anchor text | E1: Why this source | F1: Status
A2: https://www.harbourdental.example/services/teeth-whitening/ | B2: https://www.harbourdental.example/blog/teeth-whitening-cost/ | C2: 64 | D2: teeth whitening | E2: Already ranks for 'teeth whiten' terms and earns 64 clicks | F2: To do
A3: https://www.harbourdental.example/services/invisalign/ | B3: https://www.harbourdental.example/blog/invisalign-vs-braces/ | C3: 57 | D3: invisalign cost | E3: Already ranks for 'invisalign' terms and earns 57 clicks | F3: To do
A4: https://www.harbourdental.example/blog/how-long-do-dental-implants-last/ | B4: https://www.harbourdental.example/services/dental-implants/ | C4: 131 | D4: how long do dental implants last | E4: Already ranks for 'implant' terms and earns 131 clicks | F4: To do
A5: https://www.harbourdental.example/services/dental-implants/ | B5: https://www.harbourdental.example/blog/how-long-do-dental-implants-last/ | C5: 74 | D5: dental implants | E5: Already ranks for 'implant' terms and earns 74 clicks | F5: To do
A6: https://www.harbourdental.example/blog/teeth-whitening-cost/ | B6: https://www.harbourdental.example/services/teeth-whitening/ | C6: 512 | D6: teeth whitening cost | E6: Already ranks for 'teeth whiten' terms and earns 512 clicks | F6: To do
A7: https://www.harbourdental.example/services/root-canal/ | B7: https://www.harbourdental.example/services/emergency-dentist/ | C7: 782 | D7: root canal treatment | E7: Strongest service page; toothache and emergency visitors are often root canal candidates | F7: To do
A8: https://www.harbourdental.example/services/root-canal/ | B8: https://www.harbourdental.example/services/dental-crowns/ | C8: 18 | D8: root canal | E8: Topically linked: crowns are often placed after a root canal | F8: To do

Sheet Cannibalisation
A1: Query | B1: Total impressions | C1: Competing page | D1: Impressions | E1: Clicks | F1: Position | G1: Suggested fix
A2: teeth whitening cost | B2: 5305 | C2: https://www.harbourdental.example/blog/teeth-whitening-cost/ | D2: 3235 | E2: 26 | F2: 15.6 | G2: Pick ONE page to own this query. Point the others to it with an internal link using the query as anchor, and remove the query from their title/H1.
C3: https://www.harbourdental.example/services/teeth-whitening/ | D3: 2070 | E3: 9 | F3: 12.7

Sheet Action Plan
A1: # | B1: Priority | C1: Page | D1: Action | E1: Type | F1: Est. extra clicks / period | G1: Owner | H1: Status | I1: Date done | J1: Notes
A2: 1 | B2: High | C2: https://www.harbourdental.example/services/dental-implants/ | D2: Add 4 content chunks + 1 internal link; follow the push plan (see Page 2-3 Pages) | E2: Push to page 1 | F2: 803 | H2: To do
A3: 2 | B3: High | C3: https://www.harbourdental.example/services/root-canal/ | D3: Add 4 content chunks; follow the push plan (see Page 2-3 Pages) | E3: Push to page 1 | F3: 546 | H3: To do
A4: 3 | B4: High | C4: https://www.harbourdental.example/services/teeth-whitening/ | D4: Rewrite title + meta description (see Low CTR Pages) | E4: CTR rewrite | F4: 498 | H4: To do
